{"name": "test_with_bug", "status": "skipped", "statusDetails": {"message": "XFAIL Найден баг в приложении, из-за которого тест падает с ошибкой\n\nAssertionError: assert 1 == 2", "trace": "@pytest.mark.xfail(reason='Найден баг в приложении, из-за которого тест падает с ошибкой')\n    def test_with_bug():\n>       assert 1 == 2\nE       assert 1 == 2\n\ntests\\pytest\\test_pytest_xfail.py:6: AssertionError"}, "start": 1758544959458, "stop": 1758544959459, "uuid": "0b04efe3-27f0-48d4-aa9c-ace27c35ae99", "historyId": "fb30392daae1117f9ea61a430455c804", "testCaseId": "fb30392daae1117f9ea61a430455c804", "fullName": "tests.pytest.test_pytest_xfail#test_with_bug", "labels": [{"name": "tag", "value": "@pytest.mark.xfail(reason='Найден баг в приложении, из-за которого тест падает с ошибкой')"}, {"name": "parentSuite", "value": "tests.pytest"}, {"name": "suite", "value": "test_pytest_xfail"}, {"name": "host", "value": "McSuit"}, {"name": "thread", "value": "28276-MainThread"}, {"name": "framework", "value": "pytest"}, {"name": "language", "value": "cpython3"}, {"name": "package", "value": "tests.pytest.test_pytest_xfail"}]}