{"name": "test_with_bug", "status": "skipped", "statusDetails": {"message": "XFAIL Найден баг в приложении, из-за которого тест падает с ошибкой\n\nAssertionError: assert 1 == 2", "trace": "@pytest.mark.xfail(reason='Найден баг в приложении, из-за которого тест падает с ошибкой')\n    def test_with_bug():\n>       assert 1 == 2\nE       assert 1 == 2\n\ntests\\pytest\\test_pytest_xfail.py:6: AssertionError"}, "start": 1758642466197, "stop": 1758642466198, "uuid": "7f134da0-9552-4e71-9eb5-27104709b6cd", "historyId": "fb30392daae1117f9ea61a430455c804", "testCaseId": "fb30392daae1117f9ea61a430455c804", "fullName": "tests.pytest.test_pytest_xfail#test_with_bug", "labels": [{"name": "tag", "value": "@pytest.mark.xfail(reason='Найден баг в приложении, из-за которого тест падает с ошибкой')"}, {"name": "parentSuite", "value": "tests.pytest"}, {"name": "suite", "value": "test_pytest_xfail"}, {"name": "host", "value": "McSuit"}, {"name": "thread", "value": "14032-MainThread"}, {"name": "framework", "value": "pytest"}, {"name": "language", "value": "cpython3"}, {"name": "package", "value": "tests.pytest.test_pytest_xfail"}]}